Watching for file changes with StatReloader
[05/Jan/2025 04:33:36] "GET /api/ HTTP/1.1" 200 14603
[05/Jan/2025 04:33:47] "GET /api/ HTTP/1.1" 200 14601
[05/Jan/2025 04:33:55] "GET /api/course/ HTTP/1.1" 200 17937
/root/django-project/Educa/educa/courses/api/views.py changed, reloading.
Performing system checks...

System check identified no issues (0 silenced).
January 05, 2025 - 04:33:18
Django version 5.0.10, using settings 'educa.settings'
Starting development server at http://127.0.0.1:8000/
Quit the server with CONTROL-C.

Watching for file changes with StatReloader
Exception in thread django-main-thread:
Traceback (most recent call last):
  File "/usr/lib/python3.12/threading.py", line 1073, in _bootstrap_inner
    self.run()
  File "/usr/lib/python3.12/threading.py", line 1010, in run
    self._target(*self._args, **self._kwargs)
  File "/root/django-project/django-venv/lib/python3.12/site-packages/django/utils/autoreload.py", line 64, in wrapper
    fn(*args, **kwargs)
  File "/root/django-project/django-venv/lib/python3.12/site-packages/django/core/management/commands/runserver.py", line 133, in inner_run
    self.check(display_num_errors=True)
  File "/root/django-project/django-venv/lib/python3.12/site-packages/django/core/management/base.py", line 486, in check
    all_issues = checks.run_checks(
                 ^^^^^^^^^^^^^^^^^^
  File "/root/django-project/django-venv/lib/python3.12/site-packages/django/core/checks/registry.py", line 88, in run_checks
    new_errors = check(app_configs=app_configs, databases=databases)
                 ^^^^^^^^^^^^^^^^^^^^^^^^^^^^^^^^^^^^^^^^^^^^^^^^^^^
  File "/root/django-project/django-venv/lib/python3.12/site-packages/django/core/checks/urls.py", line 14, in check_url_config
    return check_resolver(resolver)
           ^^^^^^^^^^^^^^^^^^^^^^^^
  File "/root/django-project/django-venv/lib/python3.12/site-packages/django/core/checks/urls.py", line 24, in check_resolver
    return check_method()
           ^^^^^^^^^^^^^^
  File "/root/django-project/django-venv/lib/python3.12/site-packages/django/urls/resolvers.py", line 519, in check
    for pattern in self.url_patterns:
                   ^^^^^^^^^^^^^^^^^
  File "/root/django-project/django-venv/lib/python3.12/site-packages/django/utils/functional.py", line 47, in __get__
    res = instance.__dict__[self.name] = self.func(instance)
                                         ^^^^^^^^^^^^^^^^^^^
  File "/root/django-project/django-venv/lib/python3.12/site-packages/django/urls/resolvers.py", line 738, in url_patterns
    patterns = getattr(self.urlconf_module, "urlpatterns", self.urlconf_module)
                       ^^^^^^^^^^^^^^^^^^^
  File "/root/django-project/django-venv/lib/python3.12/site-packages/django/utils/functional.py", line 47, in __get__
    res = instance.__dict__[self.name] = self.func(instance)
                                         ^^^^^^^^^^^^^^^^^^^
  File "/root/django-project/django-venv/lib/python3.12/site-packages/django/urls/resolvers.py", line 731, in urlconf_module
    return import_module(self.urlconf_name)
           ^^^^^^^^^^^^^^^^^^^^^^^^^^^^^^^^
  File "/usr/lib/python3.12/importlib/__init__.py", line 90, in import_module
    return _bootstrap._gcd_import(name[level:], package, level)
           ^^^^^^^^^^^^^^^^^^^^^^^^^^^^^^^^^^^^^^^^^^^^^^^^^^^^
  File "<frozen importlib._bootstrap>", line 1387, in _gcd_import
  File "<frozen importlib._bootstrap>", line 1360, in _find_and_load
  File "<frozen importlib._bootstrap>", line 1331, in _find_and_load_unlocked
  File "<frozen importlib._bootstrap>", line 935, in _load_unlocked
  File "<frozen importlib._bootstrap_external>", line 995, in exec_module
  File "<frozen importlib._bootstrap>", line 488, in _call_with_frames_removed
  File "/root/django-project/Educa/educa/educa/urls.py", line 33, in <module>
    path("api/", include("courses.api.urls", namespace="api")),
                 ^^^^^^^^^^^^^^^^^^^^^^^^^^^^^^^^^^^^^^^^^^^^
  File "/root/django-project/django-venv/lib/python3.12/site-packages/django/urls/conf.py", line 39, in include
    urlconf_module = import_module(urlconf_module)
                     ^^^^^^^^^^^^^^^^^^^^^^^^^^^^^
  File "/usr/lib/python3.12/importlib/__init__.py", line 90, in import_module
    return _bootstrap._gcd_import(name[level:], package, level)
           ^^^^^^^^^^^^^^^^^^^^^^^^^^^^^^^^^^^^^^^^^^^^^^^^^^^^
  File "<frozen importlib._bootstrap>", line 1387, in _gcd_import
  File "<frozen importlib._bootstrap>", line 1360, in _find_and_load
  File "<frozen importlib._bootstrap>", line 1331, in _find_and_load_unlocked
  File "<frozen importlib._bootstrap>", line 935, in _load_unlocked
  File "<frozen importlib._bootstrap_external>", line 995, in exec_module
  File "<frozen importlib._bootstrap>", line 488, in _call_with_frames_removed
  File "/root/django-project/Educa/educa/courses/api/urls.py", line 14, in <module>
    path("subjects/", views.SubjectListView.as_view(), name="subject_list"),
                      ^^^^^^^^^^^^^^^^^^^^^
AttributeError: module 'courses.api.views' has no attribute 'SubjectListView'
/root/django-project/Educa/educa/courses/api/urls.py changed, reloading.
Performing system checks...

Watching for file changes with StatReloader
Exception in thread django-main-thread:
Traceback (most recent call last):
  File "/usr/lib/python3.12/threading.py", line 1073, in _bootstrap_inner
    self.run()
  File "/usr/lib/python3.12/threading.py", line 1010, in run
    self._target(*self._args, **self._kwargs)
  File "/root/django-project/django-venv/lib/python3.12/site-packages/django/utils/autoreload.py", line 64, in wrapper
    fn(*args, **kwargs)
  File "/root/django-project/django-venv/lib/python3.12/site-packages/django/core/management/commands/runserver.py", line 133, in inner_run
    self.check(display_num_errors=True)
  File "/root/django-project/django-venv/lib/python3.12/site-packages/django/core/management/base.py", line 486, in check
    all_issues = checks.run_checks(
                 ^^^^^^^^^^^^^^^^^^
  File "/root/django-project/django-venv/lib/python3.12/site-packages/django/core/checks/registry.py", line 88, in run_checks
    new_errors = check(app_configs=app_configs, databases=databases)
                 ^^^^^^^^^^^^^^^^^^^^^^^^^^^^^^^^^^^^^^^^^^^^^^^^^^^
  File "/root/django-project/django-venv/lib/python3.12/site-packages/django/core/checks/urls.py", line 14, in check_url_config
    return check_resolver(resolver)
           ^^^^^^^^^^^^^^^^^^^^^^^^
  File "/root/django-project/django-venv/lib/python3.12/site-packages/django/core/checks/urls.py", line 24, in check_resolver
    return check_method()
           ^^^^^^^^^^^^^^
  File "/root/django-project/django-venv/lib/python3.12/site-packages/django/urls/resolvers.py", line 519, in check
    for pattern in self.url_patterns:
                   ^^^^^^^^^^^^^^^^^
  File "/root/django-project/django-venv/lib/python3.12/site-packages/django/utils/functional.py", line 47, in __get__
    res = instance.__dict__[self.name] = self.func(instance)
                                         ^^^^^^^^^^^^^^^^^^^
  File "/root/django-project/django-venv/lib/python3.12/site-packages/django/urls/resolvers.py", line 738, in url_patterns
    patterns = getattr(self.urlconf_module, "urlpatterns", self.urlconf_module)
                       ^^^^^^^^^^^^^^^^^^^
  File "/root/django-project/django-venv/lib/python3.12/site-packages/django/utils/functional.py", line 47, in __get__
    res = instance.__dict__[self.name] = self.func(instance)
                                         ^^^^^^^^^^^^^^^^^^^
  File "/root/django-project/django-venv/lib/python3.12/site-packages/django/urls/resolvers.py", line 731, in urlconf_module
    return import_module(self.urlconf_name)
           ^^^^^^^^^^^^^^^^^^^^^^^^^^^^^^^^
  File "/usr/lib/python3.12/importlib/__init__.py", line 90, in import_module
    return _bootstrap._gcd_import(name[level:], package, level)
           ^^^^^^^^^^^^^^^^^^^^^^^^^^^^^^^^^^^^^^^^^^^^^^^^^^^^
  File "<frozen importlib._bootstrap>", line 1387, in _gcd_import
  File "<frozen importlib._bootstrap>", line 1360, in _find_and_load
  File "<frozen importlib._bootstrap>", line 1331, in _find_and_load_unlocked
  File "<frozen importlib._bootstrap>", line 935, in _load_unlocked
  File "<frozen importlib._bootstrap_external>", line 995, in exec_module
  File "<frozen importlib._bootstrap>", line 488, in _call_with_frames_removed
  File "/root/django-project/Educa/educa/educa/urls.py", line 33, in <module>
    path("api/", include("courses.api.urls", namespace="api")),
                 ^^^^^^^^^^^^^^^^^^^^^^^^^^^^^^^^^^^^^^^^^^^^
  File "/root/django-project/django-venv/lib/python3.12/site-packages/django/urls/conf.py", line 39, in include
    urlconf_module = import_module(urlconf_module)
                     ^^^^^^^^^^^^^^^^^^^^^^^^^^^^^
  File "/usr/lib/python3.12/importlib/__init__.py", line 90, in import_module
    return _bootstrap._gcd_import(name[level:], package, level)
           ^^^^^^^^^^^^^^^^^^^^^^^^^^^^^^^^^^^^^^^^^^^^^^^^^^^^
  File "<frozen importlib._bootstrap>", line 1387, in _gcd_import
  File "<frozen importlib._bootstrap>", line 1360, in _find_and_load
  File "<frozen importlib._bootstrap>", line 1331, in _find_and_load_unlocked
  File "<frozen importlib._bootstrap>", line 935, in _load_unlocked
  File "<frozen importlib._bootstrap_external>", line 995, in exec_module
  File "<frozen importlib._bootstrap>", line 488, in _call_with_frames_removed
  File "/root/django-project/Educa/educa/courses/api/urls.py", line 15, in <module>
    path("subjects/", views.SubjectListView.as_view(), name="subject_list"),
                      ^^^^^^^^^^^^^^^^^^^^^
AttributeError: module 'courses.api.views' has no attribute 'SubjectListView'
/root/django-project/Educa/educa/courses/api/urls.py changed, reloading.
Performing system checks...

Watching for file changes with StatReloader
[05/Jan/2025 04:51:04] "GET /api/ HTTP/1.1" 200 14791
/root/django-project/django-venv/lib/python3.12/site-packages/rest_framework/pagination.py:208: UnorderedObjectListWarning: Pagination may yield inconsistent results with an unordered object_list: <class 'courses.models.Subject'> QuerySet.
  paginator = self.django_paginator_class(queryset, page_size)
[05/Jan/2025 04:51:10] "GET /api/subjects/ HTTP/1.1" 200 16131
/root/django-project/Educa/educa/courses/api/views.py changed, reloading.
Performing system checks...

System check identified no issues (0 silenced).
January 05, 2025 - 04:50:54
Django version 5.0.10, using settings 'educa.settings'
Starting development server at http://127.0.0.1:8000/
Quit the server with CONTROL-C.

Watching for file changes with StatReloader
